Workbook

Sheet PromptGenerator
E1: Stage 1 | F1: Coding5s: | H1: AI-Powered Fast Track to Advanced Coding System | K1: Stage 1: | L1: =IF(H9="Topic", "[ROLE] Friendly tutor specializing in " & $I$2 & " | " & "[TASK] Teach and explain concepts clearly with correct code examples | " & "[TOPIC] " & I9 & " | " & "[LEVEL] " & G9 & " | " & "[COUNT] " & D9 & " examples | " & "[LANGUAGE CONSISTENCY RULE] ALL output text MUST be written strictly in the selected language (" & $B$6 & "). This includes translating ALL structural labels requested in this prompt (like 'Dataset Summary', 'File Type', 'Columns / Fields', 'Data Types', 'Notes', 'Analogy', 'Exercise', 'Objective', 'Expected Output') into " & $B$6 & ". Do NOT mix languages. Only code and technical identifiers remain unchanged | " & $AE$7 & " | " & "[LANGUAGE] " & $B$6 & " | " & "[HEADER RULE - STRICT] You MUST start your entire response EXACTLY with this markdown block (do not print anything before it):" & CHAR(10) & "### 🔹 Topic #" & F9 & " | Stage 1 📖 Practice | " & $I$2 & " | 📊 Level: " & G9 & " | 🌐 Coding5s.com" & CHAR(10) & "**Concept:** " & J9 & CHAR(10) & "---" & CHAR(10) & " | " & "[INTRO RULE] Include a short tutor-style sentence in " & $B$6 & " before the analogy, followed by this EXACT instruction block translated to " & $B$6 & _xlfn._LONGTEXT(": '🚨 **Your objective in this lesson:** To truly learn the new Python concepts with the Coding5s method, the best way is to manually copy the following exercises and write them out in your IDE, analyzing the comments and explanations they contain. In thi","s Stage, copying and pasting code is strictly forbidden. If you do this consciously, you will learn through pure practice and break free from tutorial hell.' | ") & "[PERSONA RULE] Act as a friendly, clear tutor | " & "[OUTPUT CONTRACT] EXACTLY " & D9 & _xlfn._LONGTEXT(" micro-examples. Structure MUST be: 1. Introduction 2. Analogy (STRICT: You MUST use the exact markdown subtitle '### 💡 Analogy:' before the real-world metaphor) 3. Micro-Examples: - Title Format (STRICT): EXACTLY '#### Exercise [N]️⃣: [Short specific de","scription of the action]' - Followed IMMEDIATELY by the exact markdown subtitle '#### 📖 Mini-Lesson:' consisting of a short conceptual introductory paragraph (3-5 sentences) COMPLEMENTED IMMEDIATELY by exactly 2-3 concise markdown bullet points (using th","e '-' symbol) breaking down the step-by-step internal behavior of Python before the single code block - Single code block - Program Output section (code block) - 🚨 Common mistake note - 🎯 Mini challenge 4. 📌 Key Takeaway | ") & "[CODE QUALITY RULE] Code MUST be clean, readable, educational, executable, and produce correct results | " & "[COMMENT RULE - STRICT] Code MUST include sufficient inline comments explaining important lines and logical blocks | " & "[COMMENT DEPTH RULE] Comments MUST explain WHAT the code does AND WHY it is written that way | " & "[EXPLANATION RULE] Explanation within 'Mini-Lección' MUST explain WHAT, WHY, HOW, and real-world context concisely | " & "[LEARNING RULE] Each example MUST highlight a key insight | " & "[COMMON MISTAKES RULE] Include a short mistake note after each example | " & "[MINI CHALLENGE RULE] Include a short reinforcement question after each example | " & "[REAL WORLD RULE] Connect each example to a real-world use case | " & "[FORMAT RULE] Only valid markdown code blocks allowed | " & "[LANGUAGE TAG RULE] ALWAYS label markdown code blocks with the correct underlying programming language (e.g., python, javascript, sql) | " & "[CONSISTENCY RULE] All examples MUST have similar complexity and length | " & "[FINAL OUTPUT RULE] Include Key Takeaway section at the end | " & IF(AJ9<>"", AJ9 & " | ", "") & "[OUTPUT] Only header, introduction, examples, outputs, notes, summary, and footer | " & "[FOOTER RULE - STRICT] End your entire response EXACTLY with this markdown string (ensure all code blocks are closed before it):" & CHAR(10) & "---" & CHAR(10) & "⚡ *Coding5s System — Learn Programming by Writing Code*" & "[CODE CONSTRAINTS] Each example MUST include: - Internal data OR dataset usage - Print key intermediate steps and the final result - MUST NOT exceed exactly " & $A9 & " lines of EXECUTABLE code (STRICT: Do NOT count comments or blank lines towards this limit) - NEVER exceed this limit of executable lines - " & IF(G9<>"Advanced", "NO classes - ", "") & "Single logical flow (no unnecessary complexity) | " & "[SYNTAX CONFIGURATION RULE] " & IF(F9>=10, "You MUST format output strings elegantly using f-strings natively.", "CRITICAL PROHIBITION: Do NOT use f-strings (f""..."") or any advanced text formatting methods yet. Use basic print() with multiple arguments separated by commas for text labels and variables.") & " | " & "[FUNCTION RULE] " & IF(G9="Beginner","Do NOT use functions unless absolutely required by the concept. Use flat, linear scripts. ",IF(G9="Intermediate","MUST use modular functions. Break down logic into reusable blocks. ","MUST use modular functions appropriately for architecture and clarity. ")) & "| " & "[FILE HANDLING RULE] Use correct loaders and enforce encoding='utf-8' and newline='' when applicable | " & "[SUPPORT FILES RULE] If env/config is used, include: 1. Instructional sentence 2. File content in markdown code block 3. BEFORE the main code | " & "[ECOSYSTEM ORIENTATION RULE] If a library or ecosystem like " & $J$3 & " is specified, you are CRITICALLY FORBIDDEN from using pure Python iterative loops (for/while). You MUST enforce the native, optimized data structures and vectorized operations of that specific library | " & "[OUTPUT FORMAT RULE] " & IF(F9>=10, "Monetary values formatted with '$', commas, 2 decimals using f-strings.", "Print raw numeric outputs directly without forcing custom monetary formatting structures yet.") & " | " & _xlfn._LONGTEXT("[DATA RULE - STRICT] A dataset MAY be provided in THIS CURRENT PROMPT. CRITICAL AMNESIA INSTRUCTION: You MUST treat this prompt as a completely isolated session. NEVER inherit, reference, or assume the existence of ANY files, CSVs, or datasets uploaded in"," previous chat turns. Evaluate ONLY the literal attachments of THIS specific message. If a NEW dataset IS attached to THIS prompt, you MUST: 1. Detect and acknowledge it BEFORE any explanation 2. Explicitly state file type 3. Describe structure (rows, col","umns, keys) 4. List columns or fields 5. Infer data types 6. Provide a structured summary IMMEDIATELY AFTER THE HEADER 7. Explicitly state that ALL examples will be based on this dataset 8. Use the dataset directly in ALL examples (DO NOT recreate data). ","If NO dataset is provided IN THIS CURRENT PROMPT: - STRICT: You MUST explicitly state 'No synthetic data file was provided for this topic. Generating dummy data.' (translate this phrase to ") & $B$6 & ") - PURGE ANY MEMORY of previous datasets. - Generate minimal realistic dummy data internally - Clearly proceed without dataset summary | " & "[DATA SUMMARY FORMAT RULE] When a dataset is present, you MUST display IMMEDIATELY AFTER THE HEADER: Dataset Summary: - File Type: - Columns / Fields: - Data Types: - Notes: | " & "[DATA TYPE RULE] Explicit casting required before calculations | " & "[DATA ROBUSTNESS RULE] Handle missing, malformed, or inconsistent data safely | " & "[BOOLEAN HANDLING RULE] Normalize boolean values before comparison | " & "[DATA CONSISTENCY RULE] Respect dataset schema | " & "[COMMENT DENSITY RULE] Beginner = high, Intermediate = medium, Advanced = lower but present in key logic | " & "[DIFFICULTY RULE] Complexity MUST match level | ", IF(H9="PROJECT", Z9, "")) -> [ROLE] Friendly tutor specializing in Elixir Fundamentals | [TASK] Teach and explain concepts clearly with correct code examples | [TOPIC] Explain and demonstrate basic tooling and CLI usage strictly using elixir, elixirc, iex, mix new, and mix run commands. | [LEVEL] Beginner | [COUNT] 3 examples | [LANGUAGE CONSISTENCY RULE] ALL output text MUST be written strictly in the selected language (Spanish). This includes translating ALL structural labels requested in this prompt (like 'Dataset Summary', 'File Type', 'Columns / Fields', 'Data Types', 'Notes', 'Analogy', 'Exercise', 'Objective', 'Expected Output') into Spanish. Do NOT mix languages. Only code and technical identifiers remain unchanged | | [LANGUAGE] Spanish | [HEADER RULE - STRICT] You MUST start your entire response EXACTLY with this markdown block (do not print anything before it): ### 🔹 Topic #1 | Stage 1 📖 Practice | Elixir Fundamentals | 📊 Level: Beginner | 🌐 Coding5s.com **Concept:** Basic Tooling & CLI (elixir, elixirc, iex, mix new, mix run) --- | [INTRO RULE] Include a short tutor-style sentence in Spanish before the analogy, followed by this EXACT instruction block translated to Spanish: '🚨 **Your objective in this lesson:** To truly learn the new Python concepts with the Coding5s method, the best way is to manually copy the following exercises and write them out in your IDE, analyzing the comments and explanations they contain. In this Stage, copying and pasting code is strictly forbidden. If you do this consciously, you will learn through pure practice and break free from tutorial hell.' | [PERSONA RULE] Act as a friendly, clear tutor | [OUTPUT CONTRACT] EXACTLY 3 micro-examples. Structure MUST be: 1. Introduction 2. Analogy (STRICT: You MUST use the exact markdown subtitle '### 💡 Analogy:' before the real-world metaphor) 3. Micro-Examples: - Title Format (STRICT): EXACTLY '#### Exercise [N]️⃣: [Short specific description of the action]' - Followed IMMEDIATELY by the exact markdown subtitle '#### 📖 Mini-Lesson:' consisting of a short conceptual introductory paragraph (3-5 sentences) COMPLEMENTED IMMEDIATELY by exactly 2-3 concise markdown bullet points (using the '-' symbol) breaking down the step-by-step internal behavior of Python before the single code block - Single code block - Program Output section (code block) - 🚨 Common mistake note - 🎯 Mini challenge 4. 📌 Key Takeaway | [CODE QUALITY RULE] Code MUST be clean, readable, educational, executable, and produce correct results | [COMMENT RULE - STRICT] Code MUST include sufficient inline comments explaining important lines and logical blocks | [COMMENT DEPTH RULE] Comments MUST explain WHAT the code does AND WHY it is written that way | [EXPLANATION RULE] Explanation within 'Mini-Lección' MUST explain WHAT, WHY, HOW, and real-world context concisely | [LEARNING RULE] Each example MUST highlight a key insight | [COMMON MISTAKES RULE] Include a short mistake note after each example | [MINI CHALLENGE RULE] Include a short reinforcement question after each example | [REAL WORLD RULE] Connect each example to a real-world use case | [FORMAT RULE] Only valid markdown code blocks allowed | [LANGUAGE TAG RULE] ALWAYS label markdown code blocks with the correct underlying programming language (e.g., python, javascript, sql) | [CONSISTENCY RULE] All examples MUST have similar complexity and length | [FINAL OUTPUT RULE] Include Key Takeaway section at the end | [OUTPUT] Only header, introduction, examples, outputs, notes, summary, and footer | [FOOTER RULE - STRICT] End your entire response EXACTLY with this markdown string (ensure all code blocks are closed before it): --- ⚡ *Coding5s System — Learn Programming by Writing Code*[CODE CONSTRAINTS] Each example MUST include: - Internal data OR dataset usage - Print key intermediate steps and the final result - MUST NOT exceed exactly 6 lines of EXECUTABLE code (STRICT: Do NOT count comments or blank lines towards this limit) - NEVER exceed this limit of executable lines - NO classes - Single logical flow (no unnecessary complexity) | [SYNTAX CONFIGURATION RULE] CRITICAL PROHIBITION: Do NOT use f-strings (f"...") or any advanced text formatting methods yet. Use basic print() with multiple arguments separated by commas for text labels and variables. | [FUNCTION RULE] Do NOT use functions unless absolutely required by the concept. Use flat, linear scripts. | [FILE HANDLING RULE] Use correct loaders and enforce encoding='utf-8' and newline='' when applicable | [SUPPORT FILES RULE] If env/config is used, include: 1. Instructional sentence 2. File content in markdown code block 3. BEFORE the main code | [ECOSYSTEM ORIENTATION RULE] If a library or ecosystem like is specified, you are CRITICALLY FORBIDDEN from using pure Python iterative loops (for/while). You MUST enforce the native, optimized data structures and vectorized operations of that specific library | [OUTPUT FORMAT RULE] Print raw numeric outputs directly without forcing custom monetary formatting structures yet. | [DATA RULE - STRICT] A dataset MAY be provided in THIS CURRENT PROMPT. CRITICAL AMNESIA INSTRUCTION: You MUST treat this prompt as a completely isolated session. NEVER inherit, reference, or assume the existence of ANY files, CSVs, or datasets uploaded in previous chat turns. Evaluate ONLY the literal attachments of THIS specific message. If a NEW dataset IS attached to THIS prompt, you MUST: 1. Detect and acknowledge it BEFORE any explanation 2. Explicitly state file type 3. Describe structure (rows, columns, keys) 4. List columns or fields 5. Infer data types 6. Provide a structured summary IMMEDIATELY AFTER THE HEADER 7. Explicitly state that ALL examples will be based on this dataset 8. Use the dataset directly in ALL examples (DO NOT recreate data). If NO dataset is provided IN THIS CURRENT PROMPT: - STRICT: You MUST explicitly state 'No synthetic data file was provided for this topic. Generating dummy data.' (translate this phrase to Spanish) - PURGE ANY MEMORY of previous datasets. - Generate minimal realistic dummy data internally - Clearly proceed without dataset summary | [DATA SUMMARY FORMAT RULE] When a dataset is present, you MUST display IMMEDIATELY AFTER THE HEADER: Dataset Summary: - File Type: - Columns / Fields: - Data Types: - Notes: | [DATA TYPE RULE] Explicit casting required before calculations | [DATA ROBUSTNESS RULE] Handle missing, malformed, or inconsistent data safely | [BOOLEAN HANDLING RULE] Normalize boolean values before comparison | [DATA CONSISTENCY RULE] Respect dataset schema | [COMMENT DENSITY RULE] Beginner = high, Intermediate = medium, Advanced = lower but present in key logic | [DIFFICULTY RULE] Complexity MUST match level | | N1: Stage 2: | Q1: Stage 3: | T1: Stage 4: | W1: Stage 5:
A2: a | E2: =IF(E1="Stage 1","k9:L200",IF(E1="Stage 2","N9:O200",IF(E1="Stage 3","Q9:R200",IF(E1="Stage 4","T9:U200",IF(E1="Stage 5","W9:X200","Stage Incorrecta"))))) -> k9:L200 | F2: Learning Now: | I2: Elixir Fundamentals | K2: Initial learning path | N2: Debugging broken code | Q2: Completing blank code lines | T2: Cleaning dirty working code | W2: Expanding good working code
A3: ="" | C3: Has Synthetic Dataset: | E3: =COUNTA(E9:E200)-E4 -> 12 | F3: Target Library:
C4: No Dataset: | E4: =COUNTIF($E$9:$E$200,"No") -> 65
B5: Language: | C5: Abr. | E5: Languages Range | K5: =IF(H9<>"PROJECT","", "[TASK] Teach through a practical " & $I$2 & " - " & $I$3 & " project following the micro-learning methodology, acting as a supportive tutor, creating a project about " & I9 & " | " & "[TOPICS USED] " & B9 & " | " & "[LEVEL] " & G9 & " | " & "[LIBRARY BEING LEARNED] " & $I$3 & " | " & "[LANGUAGE CONSISTENCY RULE] ALL output MUST be strictly in " & $B$6 & ". This includes translating ALL structural labels requested in this prompt (like 'Project', 'Objective', 'Support File', 'Code Planning', 'Libraries', 'Functional Structure', 'Friction Point', 'Expected Output', 'Code') into " & $B$6 & ". Do NOT mix languages. Only code and technical identifiers remain unchanged | " & $AE$7 & " | " & "[LANGUAGE SEED CONTEXT] " & IF($AE$7 = "", "Language Seed Not Necessary", "You MUST strictly follow this seed context to enhance, adapt, and naturalize your tone, vocabulary, and instructional quality in " & $B$6 & ": " & $AE$7) & " | " & "[LANGUAGE] " & $B$6 & " | " & "[INLINE_PACKAGE_MANAGER] If the project requires an external package, you MUST use Mix.install([{:package_name, '~> version'}]) at the top. | " & "[SCOPE_ARCHITECTURE_RULE] Rule: Use well-structured modules, public (def)/private (defp) APIs and immutability. | " & _xlfn._LONGTEXT("[VISUAL_ARCHITECTURE_COMMENTS] 1. Use visual block tags (e.g., '# --- BLOQUE 1: [NAME] ---') to map code to the planning phase. 2. Use comprehensive documentation using @moduledoc and @doc. 3. CRITICAL: NO comment or docstring line may exceed 80 character","s in width. | ") & "[DATA ROBUSTNESS RULE] Handle real-world data safely | " & "[CODE CONSTRAINTS] MUST be between " & IF(G9="Beginner", "25–40", IF(G9="Intermediate", "30–60", "40–100")) & " lines (STRICT) - Multi-step flow | " & "[SUPPORT FILES RULE] Include config files before code if needed | " & _xlfn._LONGTEXT("[DATA RULE - STRICT] CRITICAL AMNESIA INSTRUCTION: You MUST treat this prompt as a completely isolated session. NEVER inherit, reference, or assume the existence of ANY files, CSVs, or datasets from previous chat turns. Evaluate ONLY the literal attachmen","ts of THIS specific input. If a NEW dataset is provided in THIS CURRENT PROMPT, you MUST detect, summarize, and use it exactly as defined in Topic rules, displaying the summary IMMEDIATELY AFTER THE HEADER. If NO dataset is explicitly attached NOW, you MU","ST state 'No dataset provided for this project' (translate this phrase to ") & $B$6 & ") IMMEDIATELY AFTER THE HEADER, PURGE any memory of previous files, and use realistic dummy data | " & _xlfn._LONGTEXT("[OUTPUT CONTRACT] EXACTLY 1 project following this structure: 1. Objective (friendly tone) 2. Support File (if mock text file is needed, provide plaintext block) 3. Code Planning (List Libraries, outline Functional Structure mapped to blocks, and include ","ONE '⚠️ Friction Point/Gotcha' warning) 4. Expected Output 5. Code | ") & "[CODE QUALITY RULE] Code MUST be clean, readable, correct, and educational | " & "[FORMAT RULE] Only markdown code blocks allowed | " & "[EXECUTION RULE] Code MUST run and produce correct output | " & "[CONSISTENCY RULE] Project must match objective | " & "[HEADER RULE - STRICT] You MUST start your entire response EXACTLY with this markdown block (do not print anything before it):" & CHAR(10) & "### 🚀 Project #" & F9 & " | Stage 1 | " & IF($I$3="", $I$2, $I$2& " - " &$I$3) & " | 📊 Level: " & G9 & " | 🌐 Coding5s.com" & CHAR(10) & "**Project:** " & J9 & CHAR(10) & "---" & CHAR(10) & " | " & "[OUTPUT] Only header, dataset notice, objective, support file, code planning, expected output, code, and footer | " & "[FOOTER RULE - STRICT] End your entire response EXACTLY with this markdown string (ensure all code blocks are closed before it):" & CHAR(10) & "---" & CHAR(10) & "⚡ *Coding5s System — Learn Programming by Writing Code*")
B6: Spanish | C6: =VLOOKUP(B6,AL:AM,2,0) -> es | E6: {="AL9:"&ADDRESS(_xlfn.AGGREGATE(14, 6, ROW(AL:AL)*(AL:AL<>""), 1), COLUMN(AL:AL))} -> AL9:$AL$48 | AE6: Seed Context:
K7: updated | L7: updated | N7: updated | O7: updated | Q7: updated | R7: updated | T7: updated | U7: updated | W7: updated | X7: updated | Z7: updated | AA7: updated | AB7: updated | AC7: updated | AD7: updated | AE7: =_xlfn.CONCAT(AH9:AH200) | AK7: Testing Languages
A8: Max Lines | B8: Project Topics | C8: 0 | D8: Number of Examples | E8: Synthetic Data | F8: # | G8: Level | H8: Type | I8: Topic for AI | J8: Topic Name | K8: Stage 1 Prompt | L8: Mentor Prompt | M8: Track | N8: Stage 2 Prompt | O8: Mentor Prompt | P8: Track2 | Q8: Stage 3 Prompt | R8: Mentor Prompt | S8: Track3 | T8: Stage 4 Prompt | U8: Mentor Prompt | V8: Track4 | W8: Stage 5 Prompt | X8: Mentor Prompt | Y8: Track5 | Z8: Stage1 Project | AA8: Stage2 Project | AB8: Stage3 Project | AC8: Stage4 Project | AD8: Stage5 Project | AE8: Low Resource Lang | AF8: Abbreviation | AG8: Language Seed Context | AH8: Seed To Use | AI8: Seed context for translating text | AJ8: Manual Variables by Topic | AK8: No. | AL8: Language | AM8: Abr.
